<sdf version='1.8'>
  <model name="waffle">
    <pose>0 0 0 0 0 0</pose>

    <!-- FIX 1: base_footprint must be empty (no inertial tag) -->
    <link name="base_footprint"/>

    <link name="base_link">
      <inertial>
        <pose>-0.064 0 0.048 0 0 0</pose>
        <inertia>
          <ixx>4.2111447e-02</ixx>
          <ixy>0</ixy>
          <ixz>0</ixz>
          <iyy>4.2111447e-02</iyy>
          <iyz>0</iyz>
          <izz>7.5254874e-02</izz>
        </inertia>
        <mass>1.3729096e+00</mass>
      </inertial>
      <collision name="base_collision">
        <pose>-0.064 0 0.048 0 0 0</pose>
        <geometry>
          <box>
            <size>0.265 0.265 0.089</size>
          </box>
        </geometry>
      </collision>
      <visual name="base_visual">
        <pose>-0.064 0 0 0 0 0</pose>
        <geometry>
          <mesh>
            <uri>model://turtlebot3/waffle/meshes/waffle_base.dae</uri>
            <scale>0.001 0.001 0.001</scale>
          </mesh>
        </geometry>
        <material>
          <diffuse> 0.921568627 0.925490196 0.941176471 1</diffuse>
          <ambient> 0.921568627 0.925490196 0.941176471 1</ambient>
          <specular>0.921568627 0.925490196 0.941176471 1</specular>
        </material>
      </visual>
    </link>

    <joint name="base_joint" type="fixed">
      <parent>base_footprint</parent>
      <child>base_link</child>
      <!-- Adjust pose so base_link is slightly above ground relative to footprint -->
      <pose>0 0 0.01 0 0 0</pose>
    </joint>

    <!-- IMU -->
    <link name="imu_link">
      <!-- FIX 2: Added a tiny inertial tag so the sensor is recognized properly -->
      <inertial>
        <mass>0.01</mass>
        <inertia>
          <ixx>1e-5</ixx>
          <ixy>0</ixy>
          <ixz>0</ixz>
          <iyy>1e-5</iyy>
          <iyz>0</iyz>
          <izz>1e-5</izz>
        </inertia>
      </inertial>
      <sensor name="imu" type="imu">
        <always_on>1</always_on>
        <update_rate>200</update_rate>
        <visualize>true</visualize>
        <topic>imu</topic>
        <gz_frame_id>imu_link</gz_frame_id>
        <imu/>
      </sensor>
    </link>

    <joint name="imu_joint" type="fixed">
      <pose>-0.032 0 0.068 0 0 0</pose>
      <parent>base_link</parent>
      <child>imu_link</child>
    </joint>

    <!-- LIDAR -->
    <link name="base_scan">
      <inertial>
        <pose>-0.052 0 0.111 0 0 0</pose>
        <inertia>
          <ixx>0.001</ixx>
          <ixy>0</ixy>
          <ixz>0</ixz>
          <iyy>0.001</iyy>
          <iyz>0</iyz>
          <izz>0.001</izz>
        </inertia>
        <mass>0.114</mass>
      </inertial>
      <collision name="lidar_sensor_collision">
        <pose>-0.052 0 0.111 0 0 0</pose>
        <geometry>
          <cylinder>
            <radius>0.0508</radius>
            <length>0.055</length>
          </cylinder>
        </geometry>
      </collision>
      <visual name="lidar_sensor_visual">
        <pose>-0.064 0 0.121 0 0 0</pose>
        <geometry>
          <mesh>
            <uri>model://turtlebot3/waffle/meshes/lds.dae</uri>
            <scale>0.001 0.001 0.001</scale>
          </mesh>
        </geometry>
      </visual>
      <sensor name="gpu_lidar" type="gpu_lidar">
        <pose>-0.064 0 0.121 0 0 0</pose>
        <topic>scan</topic>
        <gz_frame_id>base_scan</gz_frame_id>
        <update_rate>5</update_rate>
        <ray>
          <scan>
            <horizontal>
              <samples>360</samples>
              <resolution>1</resolution>
              <min_angle>0</min_angle>
              <max_angle>6.28</max_angle>
            </horizontal>
          </scan>
          <range>
            <min>0.12</min>
            <max>20.0</max>
            <resolution>0.015</resolution>
          </range>
        </ray>
        <always_on>true</always_on>
        <visualize>1</visualize>
      </sensor>
    </link>

    <joint name="lidar_joint" type="fixed">
      <parent>base_link</parent>
      <child>base_scan</child>
    </joint>

    <!-- Wheel left -->
    <link name="wheel_left_link">
      <pose>0.0 0.144 0.023 -1.57 0 0</pose>
      <inertial>
        <mass>0.1</mass>
        <inertia>
          <ixx>1.1175580e-05</ixx>
          <iyy>1.1192413e-05</iyy>
          <izz>2.0712558e-05</izz>
        </inertia>
      </inertial>
      <collision name="wheel_left_collision">
        <geometry>
          <cylinder>
            <radius>0.033</radius>
            <length>0.018</length>
          </cylinder>
        </geometry>
      </collision>
      <visual name="wheel_left_visual">
        <geometry>
          <mesh>
            <uri>model://turtlebot3/waffle/meshes/tire.dae</uri>
            <scale>0.001 0.001 0.001</scale>
          </mesh>
        </geometry>
      </visual>
    </link>

    <joint name="wheel_left_joint" type="revolute">
      <parent>base_link</parent>
      <child>wheel_left_link</child>
      <axis>
        <xyz>0 0 1</xyz>
      </axis>
    </joint>

    <!-- Wheel right -->
    <link name="wheel_right_link">
      <pose>0.0 -0.144 0.023 -1.57 0 0</pose>
      <inertial>
        <mass>0.1</mass>
        <inertia>
          <ixx>1.1175580e-05</ixx>
          <iyy>1.1192413e-05</iyy>
          <izz>2.0712558e-05</izz>
        </inertia>
      </inertial>
      <collision name="wheel_right_collision">
        <geometry>
          <cylinder>
            <radius>0.033</radius>
            <length>0.018</length>
          </cylinder>
        </geometry>
      </collision>
      <visual name="wheel_right_visual">
        <geometry>
          <mesh>
            <uri>model://turtlebot3/waffle/meshes/tire.dae</uri>
            <scale>0.001 0.001 0.001</scale>
          </mesh>
        </geometry>
      </visual>
    </link>

    <joint name="wheel_right_joint" type="revolute">
      <parent>base_link</parent>
      <child>wheel_right_link</child>
      <axis>
        <xyz>0 0 1</xyz>
      </axis>
    </joint>

    <!-- Casters (Simplified to prevent KDL errors) -->
    <link name='caster_back_right_link'>
      <pose>-0.177 -0.064 -0.004 0 0 0</pose>
      <inertial>
        <mass>0.001</mass>
        <inertia>
          <ixx>1e-5</ixx><iyy>1e-5</iyy><izz>1e-5</izz>
        </inertia>
      </inertial>
      <collision name='collision'>
        <geometry><sphere><radius>0.005</radius></sphere></geometry>
      </collision>
    </link>
    <joint name='caster_back_right_joint' type='ball'>
      <parent>base_link</parent>
      <child>caster_back_right_link</child>
    </joint>

    <link name='caster_back_left_link'>
      <pose>-0.177 0.064 -0.004 0 0 0</pose>
      <inertial>
        <mass>0.001</mass>
        <inertia>
          <ixx>1e-5</ixx><iyy>1e-5</iyy><izz>1e-5</izz>
        </inertia>
      </inertial>
      <collision name='collision'>
        <geometry><sphere><radius>0.005</radius></sphere></geometry>
      </collision>
    </link>
    <joint name='caster_back_left_joint' type='ball'>
      <parent>base_link</parent>
      <child>caster_back_left_link</child>
    </joint>

    <!-- Plugins -->
    <plugin filename="gz-sim-odometry-publisher-system" name="gz::sim::systems::OdometryPublisher">
      <odom_publish_frequency>50</odom_publish_frequency>
      <odom_topic>/odom</odom_topic>
      <odom_frame>odom</odom_frame>
      <robot_base_frame>base_footprint</robot_base_frame>
      <tf_topic>/odom/tf</tf_topic>
    </plugin>

    <plugin filename="gz-sim-diff-drive-system" name="gz::sim::systems::DiffDrive">
      <left_joint>wheel_left_joint</left_joint>
      <right_joint>wheel_right_joint</right_joint>
      <wheel_separation>0.287</wheel_separation>
      <wheel_radius>0.033</wheel_radius>
      <topic>cmd_vel</topic>
    </plugin>

    <plugin filename="gz-sim-joint-state-publisher-system" name="gz::sim::systems::JointStatePublisher">
      <topic>joint_states</topic>
    </plugin>

  </model>
</sdf>